<?xml version="1.0" ?>
<robot name="bot" xmlns:xacro="http://www.ros.org/wiki/xacro">

<xacro:include filename="$(find bot_description)/urdf/materials.xacro" />
<xacro:include filename="$(find bot_description)/urdf/bot.ros2control" />
<xacro:include filename="$(find bot_description)/urdf/bot.gazebo" />
<link name="base_link">
  <inertial>
    <origin xyz="0.0033109410397353595 -5.22133469861568e-05 0.07955691217854448" rpy="0 0 0"/>
    <mass value="2.042124391834186"/>
    <inertia ixx="0.022549" iyy="0.029976" izz="0.045754" ixy="1e-05" iyz="7e-06" ixz="-0.000498"/>
  </inertial>
  <visual>
    <origin xyz="0 0 0" rpy="0 0 0"/>
    <geometry>
      <mesh filename="file://$(find bot_description)/meshes/base_link.stl" scale="0.001 0.001 0.001"/>
    </geometry>
    <material name="silver"/>
  </visual>
  <collision>
    <origin xyz="0 0 0" rpy="0 0 0"/>
    <geometry>
      <mesh filename="file://$(find bot_description)/meshes/base_link.stl" scale="0.001 0.001 0.001"/>
    </geometry>
  </collision>
</link>

<link name="right_wheel_link_1">
  <inertial>
    <origin xyz="-1.4135271091344188e-10 -0.028050466348318148 1.225355835798858e-06" rpy="0 0 0"/>
    <mass value="0.132130981755143"/>
    <inertia ixx="0.000164" iyy="0.000293" izz="0.000164" ixy="-0.0" iyz="-0.0" ixz="-0.0"/>
  </inertial>
  <visual>
    <origin xyz="-0.0 0.1425 -0.0546" rpy="0 0 0"/>
    <geometry>
      <mesh filename="file://$(find bot_description)/meshes/right_wheel_link_1.stl" scale="0.001 0.001 0.001"/>
    </geometry>
    <material name="silver"/>
  </visual>
  <collision>
    <origin xyz="-0.0 0.1425 -0.0546" rpy="0 0 0"/>
    <geometry>
      <mesh filename="file://$(find bot_description)/meshes/right_wheel_link_1.stl" scale="0.001 0.001 0.001"/>
    </geometry>
  </collision>
</link>

<link name="left_wheel_link_1">
  <inertial>
    <origin xyz="1.4973146092150716e-11 0.028050466283458836 -1.2262817377928226e-06" rpy="0 0 0"/>
    <mass value="0.13213095662214813"/>
    <inertia ixx="0.000164" iyy="0.000293" izz="0.000164" ixy="0.0" iyz="-0.0" ixz="0.0"/>
  </inertial>
  <visual>
    <origin xyz="0.0 -0.1425 -0.0546" rpy="0 0 0"/>
    <geometry>
      <mesh filename="file://$(find bot_description)/meshes/left_wheel_link_1.stl" scale="0.001 0.001 0.001"/>
    </geometry>
    <material name="silver"/>
  </visual>
  <collision>
    <origin xyz="0.0 -0.1425 -0.0546" rpy="0 0 0"/>
    <geometry>
      <mesh filename="file://$(find bot_description)/meshes/left_wheel_link_1.stl" scale="0.001 0.001 0.001"/>
    </geometry>
  </collision>
</link>

<link name="caster_wheel_b_1">
  <inertial>
    <origin xyz="0.01999999999999999 -2.634096614519092e-17 -0.012260416666666649" rpy="0 0 0"/>
    <mass value="0.01798247634914797"/>
    <inertia ixx="2e-06" iyy="2e-06" izz="2e-06" ixy="0.0" iyz="-0.0" ixz="-0.0"/>
  </inertial>
  <visual>
    <origin xyz="0.1675 0.0 -0.0291" rpy="0 0 0"/>
    <geometry>
      <mesh filename="file://$(find bot_description)/meshes/caster_wheel_b_1.stl" scale="0.001 0.001 0.001"/>
    </geometry>
    <material name="silver"/>
  </visual>
  <collision>
    <origin xyz="0.1675 0.0 -0.0291" rpy="0 0 0"/>
    <geometry>
      <mesh filename="file://$(find bot_description)/meshes/caster_wheel_b_1.stl" scale="0.001 0.001 0.001"/>
    </geometry>
  </collision>
</link>

<link name="caster_wheel_a_1">
  <inertial>
    <origin xyz="-0.019999999999999962 3.769546289141946e-17 -0.012260416666666652" rpy="0 0 0"/>
    <mass value="0.01798247634914797"/>
    <inertia ixx="2e-06" iyy="2e-06" izz="2e-06" ixy="0.0" iyz="-0.0" ixz="-0.0"/>
  </inertial>
  <visual>
    <origin xyz="-0.1675 -0.0 -0.0291" rpy="0 0 0"/>
    <geometry>
      <mesh filename="file://$(find bot_description)/meshes/caster_wheel_a_1.stl" scale="0.001 0.001 0.001"/>
    </geometry>
    <material name="silver"/>
  </visual>
  <collision>
    <origin xyz="-0.1675 -0.0 -0.0291" rpy="0 0 0"/>
    <geometry>
      <mesh filename="file://$(find bot_description)/meshes/caster_wheel_a_1.stl" scale="0.001 0.001 0.001"/>
    </geometry>
  </collision>
</link>

<link name="camera_link_1">
  <inertial>
    <origin xyz="0.00289127586298088 0.0010656513836692378 0.012889229339118194" rpy="0 0 0"/>
    <mass value="0.006742869777511351"/>
    <inertia ixx="0.0" iyy="0.0" izz="0.0" ixy="-0.0" iyz="0.0" ixz="-0.0"/>
  </inertial>
  <visual>
    <origin xyz="-0.1675 -0.0 -0.0791" rpy="0 0 0"/>
    <geometry>
      <mesh filename="file://$(find bot_description)/meshes/camera_link_1.stl" scale="0.001 0.001 0.001"/>
    </geometry>
    <material name="silver"/>
  </visual>
  <collision>
    <origin xyz="-0.1675 -0.0 -0.0791" rpy="0 0 0"/>
    <geometry>
      <mesh filename="file://$(find bot_description)/meshes/camera_link_1.stl" scale="0.001 0.001 0.001"/>
    </geometry>
  </collision>
</link>

<link name="lidar_link_1">
  <inertial>
    <origin xyz="-0.0006078599059984313 -0.00013002224629664804 0.014307180955488885" rpy="0 0 0"/>
    <mass value="0.053104251406073145"/>
    <inertia ixx="2.4e-05" iyy="2.4e-05" izz="4.4e-05" ixy="0.0" iyz="-0.0" ixz="-0.0"/>
  </inertial>
  <visual>
    <origin xyz="-0.115878 0.002021 -0.163831" rpy="0 0 0"/>
    <geometry>
      <mesh filename="file://$(find bot_description)/meshes/lidar_link_1.stl" scale="0.001 0.001 0.001"/>
    </geometry>
    <material name="silver"/>
  </visual>
  <collision>
    <origin xyz="-0.115878 0.002021 -0.163831" rpy="0 0 0"/>
    <geometry>
      <mesh filename="file://$(find bot_description)/meshes/lidar_link_1.stl" scale="0.001 0.001 0.001"/>
    </geometry>
  </collision>
</link>

<joint name="right_wheel_joint" type="continuous">
  <origin xyz="0.0 -0.1425 0.0546" rpy="0 0 0"/>
  <parent link="base_link"/>
  <child link="right_wheel_link_1"/>
  <axis xyz="0.0 -1.0 0.0"/>
</joint>

<joint name="left_wheel_joint" type="continuous">
  <origin xyz="0.0 0.1425 0.0546" rpy="0 0 0"/>
  <parent link="base_link"/>
  <child link="left_wheel_link_1"/>
  <axis xyz="0.0 -1.0 0.0"/>
</joint>

<joint name="caster_wheel_b_joint" type="fixed">
  <origin xyz="-0.1675 0.0 0.0291" rpy="0 0 0"/>
  <parent link="base_link"/>
  <child link="caster_wheel_b_1"/>
</joint>

<joint name="caster_wheel_a_joint" type="fixed">
  <origin xyz="0.1675 0.0 0.0291" rpy="0 0 0"/>
  <parent link="base_link"/>
  <child link="caster_wheel_a_1"/>
</joint>

<joint name="camera_joint" type="fixed">
  <origin xyz="0.1675 0.0 0.0791" rpy="0 0 0"/>
  <parent link="base_link"/>
  <child link="camera_link_1"/>
</joint>

<joint name="lidar_joint" type="fixed">
  <origin xyz="0.115878 -0.002021 0.163831" rpy="0 0 0"/>
  <parent link="base_link"/>
  <child link="lidar_link_1"/>
</joint>

</robot>
